Workbook
Name BidangList: DATA!$A$4:$A$203
Name K_1: DATA!$B$4:$B$53
Name K_10: DATA!$K$4:$K$53
Name K_100: DATA!$CW$4:$CW$53
Name K_101: DATA!$CX$4:$CX$53
Name K_102: DATA!$CY$4:$CY$53
Name K_103: DATA!$CZ$4:$CZ$53
Name K_104: DATA!$DA$4:$DA$53
Name K_105: DATA!$DB$4:$DB$53
Name K_106: DATA!$DC$4:$DC$53
Name K_107: DATA!$DD$4:$DD$53
Name K_108: DATA!$DE$4:$DE$53
Name K_109: DATA!$DF$4:$DF$53
Name K_11: DATA!$L$4:$L$53
Name K_110: DATA!$DG$4:$DG$53
Name K_111: DATA!$DH$4:$DH$53
Name K_112: DATA!$DI$4:$DI$53
Name K_113: DATA!$DJ$4:$DJ$53
Name K_114: DATA!$DK$4:$DK$53
Name K_115: DATA!$DL$4:$DL$53
Name K_116: DATA!$DM$4:$DM$53
Name K_117: DATA!$DN$4:$DN$53
Name K_118: DATA!$DO$4:$DO$53
Name K_119: DATA!$DP$4:$DP$53
Name K_12: DATA!$M$4:$M$53
Name K_120: DATA!$DQ$4:$DQ$53
Name K_121: DATA!$DR$4:$DR$53
Name K_122: DATA!$DS$4:$DS$53
Name K_123: DATA!$DT$4:$DT$53
Name K_124: DATA!$DU$4:$DU$53
Name K_125: DATA!$DV$4:$DV$53
Name K_126: DATA!$DW$4:$DW$53
Name K_127: DATA!$DX$4:$DX$53
Name K_128: DATA!$DY$4:$DY$53
Name K_129: DATA!$DZ$4:$DZ$53
Name K_13: DATA!$N$4:$N$53
Name K_130: DATA!$EA$4:$EA$53
Name K_131: DATA!$EB$4:$EB$53
Name K_132: DATA!$EC$4:$EC$53
Name K_133: DATA!$ED$4:$ED$53
Name K_134: DATA!$EE$4:$EE$53
Name K_135: DATA!$EF$4:$EF$53
Name K_136: DATA!$EG$4:$EG$53
Name K_137: DATA!$EH$4:$EH$53
Name K_138: DATA!$EI$4:$EI$53
Name K_139: DATA!$EJ$4:$EJ$53
Name K_14: DATA!$O$4:$O$53
Name K_140: DATA!$EK$4:$EK$53
Name K_141: DATA!$EL$4:$EL$53
Name K_142: DATA!$EM$4:$EM$53
Name K_143: DATA!$EN$4:$EN$53
Name K_144: DATA!$EO$4:$EO$53
Name K_145: DATA!$EP$4:$EP$53
Name K_146: DATA!$EQ$4:$EQ$53
Name K_147: DATA!$ER$4:$ER$53
Name K_148: DATA!$ES$4:$ES$53
Name K_149: DATA!$ET$4:$ET$53
Name K_15: DATA!$P$4:$P$53
Name K_150: DATA!$EU$4:$EU$53
Name K_151: DATA!$EV$4:$EV$53

Sheet READ ME
B2: KETERANGAN WARNA — KERTAS KERJA SPMB-PT PKN STAN 2026
B4: BAGIAN 1 — Kolom "Status Pilihan Prodi" (Kolom J)
B5: Warna berubah otomatis sesuai kondisi kelengkapan dan kebenaran pilihan prodi tujuan:
B6: Tampilan | C6: Status / Kondisi | D6: Keterangan
C7: Terdapat Pilihan Tidak Sesuai Prodi Asal | D7: Satu atau lebih pilihan tidak sesuai prodi asal. Perbaiki pilihan yang berwarna UNGU di kolom prodi tujuan.
C8: Pilihan Melebihi Jumlah yang Tersedia | D8: Jumlah pilihan melebihi total yang tersedia. Periksa dan kurangi pilihan.
C9: Terdapat Pilihan yang Sama / Duplikat | D9: Ada dua atau lebih pilihan prodi tujuan yang sama. Ubah pilihan yang berwarna MERAH di kolom prodi tujuan.
C10: Seluruh Pilihan Telah Terisi dengan Benar | D10: Semua slot pilihan terisi dan tidak ada masalah.
C11: Masih Terdapat Pilihan yang Bisa Dipilih | D11: Pilihan belum diisi seluruhnya. Disarankan melengkapi semua pilihan yang tersedia.
B13: BAGIAN 2 — Kolom "Prodi Tujuan dan Jalur SPMB-PT" (Pilihan 1 s.d. maks)
B14: Warna muncul otomatis jika terjadi kondisi berikut. Pilihan berwarna TIDAK dimunculkan kodenya di sheet INPUT.
B15: Tampilan | C15: Status / Kondisi | D15: Keterangan
C16: Pilihan Duplikat | D16: Nilai pilihan sama dengan pilihan lain di baris yang sama. Ganti dengan pilihan berbeda.
C17: Pilihan Tidak Sesuai Prodi Asal | D17: Pilihan tidak dalam daftar yang diperbolehkan untuk prodi asal. Ganti prodi asal atau ubah pilihan.
B19: BAGIAN 3 — Kolom "NIP" (Kolom E) — Validasi Data
B20: Warna muncul pada SELURUH BARIS apabila NIP tidak valid. Dua kondisi yang dideteksi:
B21: Tampilan | C21: Status / Kondisi | D21: Keterangan
C22: NIP Tidak Berjumlah 18 Karakter | D22: NIP kurang atau lebih dari 18 karakter. Seluruh baris ditandai merah muda. Periksa dan perbaiki.
C23: NIP Duplikat | D23: NIP yang sama sudah ada di baris lain. Kedua baris ditandai merah muda. Periksa dan perbaiki.
B25: BAGIAN 4 — Sheet INPUT (Kode KLP)
B26: Kolom KODE KLP terisi OTOMATIS hanya untuk peserta dengan Kesimpulan Akhir = "Direkomendasikan". Kode hanya muncul jika: (1) Sesuai prodi asal — tidak UNGU; (2) Tidak duplikat — tidak MERAH. Pilihan yang berwarna otomatis dikosongkan kodenya.
B29: CATATAN PENTING
B30: • Kolom STATUS PILIHAN PRODI (J) dan _avail berisi formula otomatis — JANGAN diubah.
B31: • Kolom KESIMPULAN AKHIR hanya via dropdown: "Direkomendasikan" atau "Tidak Direkomendasikan".
B32: • Isi hanya: Unit/Satuan Kerja (B-D), NIP (E), Nama (F), Email (G), Prodi Asal (I), Pilihan Prodi Tujuan (K dst.), verifikasi PMK, Kesimpulan Akhir.
B33: • Pilihan Prodi Tujuan gunakan dropdown — pilih sesuai prodi asal.
B34: • Jika Prodi Asal diubah, pilihan tidak sesuai berwarna UNGU — periksa dan perbaiki.
B35: • NIP tidak valid (bukan 18 karakter atau duplikat) mewarnai SELURUH BARIS merah muda.

Sheet checklistPesertaKemenkeu
A1: FORMULIR KERTAS KERJA SPMB-PT PKN STAN TAHUN 2026 - KEMENTERIAN KEUANGAN
A2: Data Awal | S2: Checklist Non-Dokumen | AG2: Checklist Dokumen | AZ2: Keterangan
R3: Kesesuaian Dengan Pasal 6 PMK 34 Tahun 2024 | AG3: Kelengkapan Dokumen (Subjek: Peserta) | AU3: Kelengkapan Dokumen (Subjek: Peserta dan Unit Kerja) | AV3: Kelengkapan Dokumen (Subjek: Unit Kerja) | AY3: Kesimpulan Akhir (Direkomendasikan / Tidak Direkomendasikan) | AZ3: Lainnya
AG4: 1 | AH4: 2 | AI4: 3 | AJ4: 4 | AK4: 5 | AL4: 6 | AM4: 7 | AN4: 8 | AO4: 9 | AP4: 10 | AQ4: 11 | AR4: 12 | AS4: 13 | AT4: 14 | AU4: 15 | AV4: 16 | AW4: 17 | AX4: 18 | AZ4: 19
A5: No | B5: Unit Kerja | C5: Unit/Satuan Kerja | D5: Nama PIC Unit/Satuan Kerja | E5: JALUR | F5: NIP | G5: NAMA | H5: EMAIL | I5: ID INSTANSI | J5: PRODI ASAL | K5: STATUS PILIHAN PRODI | L5: PRIORITAS PILIHAN PRODI 1 | M5: PRIORITAS PILIHAN PRODI 2 | N5: PRIORITAS PILIHAN PRODI 3 | O5: PRIORITAS PILIHAN PRODI 4 | P5: PRIORITAS PILIHAN PRODI 5 | Q5: _avail | R5: Kesesuaian antara Pendidikan Awal dengan Prodi Tujuan | S5: Memenuhi Masa Kerja Minimal PNS | T5: Memenuhi Ketentuan Sisa Masa Kerja | U5: Memenuhi Ketentuan Pangkat/Golongan Minimal | V5: Tidak sedang menjalani/dicalonkan pada program Tugas Belajar Dibiayai lain dan/atau program Tugas Belajar Mandiri Diberhentikan | W5: Belum pernah menyelesaikan program Tugas Belajar pada jenjang pendidikan yang sama; | X5: Memenuhi Ketentuan Predikat Kinerja | Y5: Tidak pernah dibatalkan/dihentikan tugas belajarnya dalam waktu 2 tahun terakhir | Z5: Tidak sedang dalam pemeriksaan atau dalam masa tunggu hasil pemeriksaan atas pelanggaran etika, disiplin, dan/atau hukum pidana penjara/kurungan | AA5: Tidak sedang menjalani pidana penjara/kurungan dan/atau hukuman disiplin; | AB5: Tidak pernah menjalani hukuman pidana penjara/kurungan dan/atau hukuman disiplin sedang atau berat dalam 1 tahun terakhir; | AC5: Tidak sedang menjalani cuti di luar tanggungan negara dan/atau menjalani pemberhentian sementara sebagai PNS | AD5: Memenuhi Masa Kerja Minimal Setelah Menyelesaikan Tugas Belajar | AE5: Mendapat persetujuan atasan langsung | AF5: Sehat Jasmani dan Rohani | AG5: Pasfoto Berwarna Berformat .jpg (3 Bulan Terakhir) (PIC: Peserta) | AH5: Scan Surat Keterangan Sehat dari Rumah Sakit Pemerintah Berformat PDF (PIC: Peserta) | AI5: Scan Surat Keterangan Kesehatan Jiwa dari Rumah Sakit Pemerintah Berformat PDF (PIC: Peserta) | AJ5: Scan Surat Keterangan Bebas TBC, Hepatitis, dan HIV/AIDS dari Rumah Sakit Pemerintah Berformat PDF (PIC: Peserta) | AK5: Scan Surat Keterangan Bebas NAPZA dari Rumah Sakit Pemerintah Berformat PDF (PIC: Peserta) | AL5: Surat Pernyataan Memenuhi Persyaratan TB dan Belum Pernah Diberhentikan/ Mengundurkan Diri dari TB Sebelumnya ((TTE dan e-Materai) atau (Tanda Tangan Basah dan Materai Tempel) Berformat PDF (Subjek: Peserta) | AM5: Surat Pernyataan Pemilihan Program Studi (TTE atau Tanda Tangan Basah) Berformat PDF (Subjek: Peserta) | AN5: Surat Pernyataan Pribadi ((TTE dan e-Materai) atau (Tanda Tangan Basah dan Materai Tempel) Berformat PDF (Subjek: Peserta) | AO5: Scan SK Pengangkatan sebagai PNS (Asli/Dilegalisasi) Berformat PDF (Subjek: Peserta) | AP5: Scan SK Kenaikan Pangkat Terakhir (Asli/Dilegalisasi) Berformat PDF (Subjek: Peserta) | AQ5: Scan Ijazah dan Transkrip Terakhir (Asli/Dilegalisasi) Berformat PDF (Subjek: Peserta) | AR5: Scan SPMT (Tertanggal Maksimal 23 November 2026) Berformat PDF (Subjek: Peserta) | AS5: Scan DEK + HEK Tahun 2024 dan 2025 Berformat PDF (Subjek: Peserta) | AT5: Surat Pernyataan Bersedia Mengikuti Seleksi Beasiswa Berformat PDF (Subjek: Peserta) | AU5: Surat Pernyataan tentang Pemilihan dan Persetujuan Alokasi Program Studi (TTE atau Tanda Tangan Basah) Berformat PDF (Subjek: Peserta dan Unit Kerja) | AV5: Surat Keterangan Kepala Unit Kerja terkait Pendidikan dan Hukuman Disiplin (TTE atau Tanda Tangan Basah dan Stempel) Berformat PDF (Subjek: Unit Kerja) | AW5: Surat Rekomendasi Kepala Unit Kerja (TTE atau Tanda Tangan Basah dan Stemple) Berformat PDF (PIC: Unit Kerja) | AX5: Nota Dinas Usulan Pendaftar SPMB TB (TTE atau Tanda Tangan Basah dan Stempel) Berformat PDF (Subjek: Unit Kerja) | AZ5: Link Penting
A6: =IF(F6="","",ROW()-5) | I6: =IF(AND(LEN(F6)=18, ISBLANK(G6)=FALSE(), ISBLANK(H6)=FALSE()),37,"") | K6: =IF(OR(J6="",Q6=0),"",IF(COUNTA(L6:P6)>Q6,"Seluruh pilihan telah dipilih, anda memilih lebih dari kemungkinan pilihan yang tersedia, periksa pilihan anda "&"("&COUNTA(L6:P6)&"/"&Q6&")",IF(COUNTA(L6:P6)=Q6,IF(SUMPRODUCT(COUNTIF(L6:P6,L6:P6)*(L6:P6<>""))>COUNTA(L6:P6),"Terdapat pilihan yang sama, segera ubah "&"("&COUNTA(L6:P6)&"/"&Q6&")","Seluruh pilihan telah dipilih "&"("&COUNTA(L6:P6)&"/"&Q6&")"),IF(COUNTA(L6:P6)>0,"Masih terdapat pilihan yang bisa dipilih, silahkan melengkapi pilihan "&"("&COUNTA(L6:P6)&"/"&Q6&")","")))) | Q6: =IFERROR(COUNTA(INDIRECT("K_"&MATCH(J6,BidangList,0))),0) -> 1 | S6: Wajib untuk Semua Unit Kerja | T6: Wajib untuk Semua Unit Kerja | U6: Wajib untuk Semua Unit Kerja | V6: Wajib untuk Semua Unit Kerja | W6: Wajib untuk Semua Unit Kerja | X6: Wajib untuk Semua Unit Kerja | Y6: Wajib untuk Semua Unit Kerja | Z6: Wajib untuk Semua Unit Kerja | AA6: Wajib untuk Semua Unit Kerja | AB6: Wajib untuk Semua Unit Kerja | AC6: Wajib untuk Semua Unit Kerja | AD6: Wajib untuk Semua Unit Kerja | AE6: Wajib untuk Semua Unit Kerja | AF6: Wajib untuk Semua Unit Kerja | AG6: Wajib untuk Semua Unit Kerja | AH6: Wajib untuk Semua Unit Kerja | AI6: Wajib untuk Semua Unit Kerja | AJ6: Wajib untuk Semua Unit Kerja | AK6: Wajib untuk Semua Unit Kerja | AL6: Wajib untuk Semua Unit Kerja | AM6: Wajib untuk DJBC | AN6: Wajib untuk DJBC | AO6: Wajib untuk DJBC dan DJP | AP6: Wajib untuk DJBC dan DJP | AQ6: Wajib untuk Semua Unit Kerja | AR6: Wajib untuk DJBC | AS6: Wajib untuk DJBC dan DJP | AT6: Wajib untuk DJP | AU6: Wajib untuk Semua Unit Kerja | AV6: Wajib untuk DJBC dan DJP | AW6: Wajib untuk Semua Unit Kerja | AX6: Wajib untuk Semua Unit Kerja | AZ6: Wajib untuk Semua Unit Kerja
A7: =IF(F7="","",ROW()-5) | I7: =IF(AND(LEN(F7)=18, ISBLANK(G7)=FALSE(), ISBLANK(H7)=FALSE()),37,"") | K7: =IF(OR(J7="",Q7=0),"",IF(COUNTA(L7:P7)>Q7,"Seluruh pilihan telah dipilih, anda memilih lebih dari kemungkinan pilihan yang tersedia, periksa pilihan anda "&"("&COUNTA(L7:P7)&"/"&Q7&")",IF(COUNTA(L7:P7)=Q7,IF(SUMPRODUCT(COUNTIF(L7:P7,L7:P7)*(L7:P7<>""))>COUNTA(L7:P7),"Terdapat pilihan yang sama, segera ubah "&"("&COUNTA(L7:P7)&"/"&Q7&")","Seluruh pilihan telah dipilih "&"("&COUNTA(L7:P7)&"/"&Q7&")"),IF(COUNTA(L7:P7)>0,"Masih terdapat pilihan yang bisa dipilih, silahkan melengkapi pilihan "&"("&COUNTA(L7:P7)&"/"&Q7&")","")))) | Q7: =IFERROR(COUNTA(INDIRECT("K_"&MATCH(J7,BidangList,0))),0) -> 1
A8: =IF(F8="","",ROW()-5) | I8: =IF(AND(LEN(F8)=18, ISBLANK(G8)=FALSE(), ISBLANK(H8)=FALSE()),37,"") | K8: =IF(OR(J8="",Q8=0),"",IF(COUNTA(L8:P8)>Q8,"Seluruh pilihan telah dipilih, anda memilih lebih dari kemungkinan pilihan yang tersedia, periksa pilihan anda "&"("&COUNTA(L8:P8)&"/"&Q8&")",IF(COUNTA(L8:P8)=Q8,IF(SUMPRODUCT(COUNTIF(L8:P8,L8:P8)*(L8:P8<>""))>COUNTA(L8:P8),"Terdapat pilihan yang sama, segera ubah "&"("&COUNTA(L8:P8)&"/"&Q8&")","Seluruh pilihan telah dipilih "&"("&COUNTA(L8:P8)&"/"&Q8&")"),IF(COUNTA(L8:P8)>0,"Masih terdapat pilihan yang bisa dipilih, silahkan melengkapi pilihan "&"("&COUNTA(L8:P8)&"/"&Q8&")","")))) | Q8: =IFERROR(COUNTA(INDIRECT("K_"&MATCH(J8,BidangList,0))),0) -> 1
A9: =IF(F9="","",ROW()-5) | I9: =IF(AND(LEN(F9)=18, ISBLANK(G9)=FALSE(), ISBLANK(H9)=FALSE()),37,"") | K9: =IF(OR(J9="",Q9=0),"",IF(COUNTA(L9:P9)>Q9,"Seluruh pilihan telah dipilih, anda memilih lebih dari kemungkinan pilihan yang tersedia, periksa pilihan anda "&"("&COUNTA(L9:P9)&"/"&Q9&")",IF(COUNTA(L9:P9)=Q9,IF(SUMPRODUCT(COUNTIF(L9:P9,L9:P9)*(L9:P9<>""))>COUNTA(L9:P9),"Terdapat pilihan yang sama, segera ubah "&"("&COUNTA(L9:P9)&"/"&Q9&")","Seluruh pilihan telah dipilih "&"("&COUNTA(L9:P9)&"/"&Q9&")"),IF(COUNTA(L9:P9)>0,"Masih terdapat pilihan yang bisa dipilih, silahkan melengkapi pilihan "&"("&COUNTA(L9:P9)&"/"&Q9&")","")))) | Q9: =IFERROR(COUNTA(INDIRECT("K_"&MATCH(J9,BidangList,0))),0) -> 1
A10: =IF(F10="","",ROW()-5) | I10: =IF(AND(LEN(F10)=18, ISBLANK(G10)=FALSE(), ISBLANK(H10)=FALSE()),37,"") | K10: =IF(OR(J10="",Q10=0),"",IF(COUNTA(L10:P10)>Q10,"Seluruh pilihan telah dipilih, anda memilih lebih dari kemungkinan pilihan yang tersedia, periksa pilihan anda "&"("&COUNTA(L10:P10)&"/"&Q10&")",IF(COUNTA(L10:P10)=Q10,IF(SUMPRODUCT(COUNTIF(L10:P10,L10:P10)*(L10:P10<>""))>COUNTA(L10:P10),"Terdapat pilihan yang sama, segera ubah "&"("&COUNTA(L10:P10)&"/"&Q10&")","Seluruh pilihan telah dipilih "&"("&COUNTA(L10:P10)&"/"&Q10&")"),IF(COUNTA(L10:P10)>0,"Masih terdapat pilihan yang bisa dipilih, silahkan melengkapi pilihan "&"("&COUNTA(L10:P10)&"/"&Q10&")","")))) | Q10: =IFERROR(COUNTA(INDIRECT("K_"&MATCH(J10,BidangList,0))),0) -> 1
A11: =IF(F11="","",ROW()-5) | I11: =IF(AND(LEN(F11)=18, ISBLANK(G11)=FALSE(), ISBLANK(H11)=FALSE()),37,"") | K11: =IF(OR(J11="",Q11=0),"",IF(COUNTA(L11:P11)>Q11,"Seluruh pilihan telah dipilih, anda memilih lebih dari kemungkinan pilihan yang tersedia, periksa pilihan anda "&"("&COUNTA(L11:P11)&"/"&Q11&")",IF(COUNTA(L11:P11)=Q11,IF(SUMPRODUCT(COUNTIF(L11:P11,L11:P11)*(L11:P11<>""))>COUNTA(L11:P11),"Terdapat pilihan yang sama, segera ubah "&"("&COUNTA(L11:P11)&"/"&Q11&")","Seluruh pilihan telah dipilih "&"("&COUNTA(L11:P11)&"/"&Q11&")"),IF(COUNTA(L11:P11)>0,"Masih terdapat pilihan yang bisa dipilih, silahkan melengkapi pilihan "&"("&COUNTA(L11:P11)&"/"&Q11&")","")))) | Q11: =IFERROR(COUNTA(INDIRECT("K_"&MATCH(J11,BidangList,0))),0) -> 1
A12: =IF(F12="","",ROW()-5) | I12: =IF(AND(LEN(F12)=18, ISBLANK(G12)=FALSE(), ISBLANK(H12)=FALSE()),37,"") | K12: =IF(OR(J12="",Q12=0),"",IF(COUNTA(L12:P12)>Q12,"Seluruh pilihan telah dipilih, anda memilih lebih dari kemungkinan pilihan yang tersedia, periksa pilihan anda "&"("&COUNTA(L12:P12)&"/"&Q12&")",IF(COUNTA(L12:P12)=Q12,IF(SUMPRODUCT(COUNTIF(L12:P12,L12:P12)*(L12:P12<>""))>COUNTA(L12:P12),"Terdapat pilihan yang sama, segera ubah "&"("&COUNTA(L12:P12)&"/"&Q12&")","Seluruh pilihan telah dipilih "&"("&COUNTA(L12:P12)&"/"&Q12&")"),IF(COUNTA(L12:P12)>0,"Masih terdapat pilihan yang bisa dipilih, silahkan melengkapi pilihan "&"("&COUNTA(L12:P12)&"/"&Q12&")","")))) | Q12: =IFERROR(COUNTA(INDIRECT("K_"&MATCH(J12,BidangList,0))),0) -> 1
A13: =IF(F13="","",ROW()-5) | I13: =IF(AND(LEN(F13)=18, ISBLANK(G13)=FALSE(), ISBLANK(H13)=FALSE()),37,"") | K13: =IF(OR(J13="",Q13=0),"",IF(COUNTA(L13:P13)>Q13,"Seluruh pilihan telah dipilih, anda memilih lebih dari kemungkinan pilihan yang tersedia, periksa pilihan anda "&"("&COUNTA(L13:P13)&"/"&Q13&")",IF(COUNTA(L13:P13)=Q13,IF(SUMPRODUCT(COUNTIF(L13:P13,L13:P13)*(L13:P13<>""))>COUNTA(L13:P13),"Terdapat pilihan yang sama, segera ubah "&"("&COUNTA(L13:P13)&"/"&Q13&")","Seluruh pilihan telah dipilih "&"("&COUNTA(L13:P13)&"/"&Q13&")"),IF(COUNTA(L13:P13)>0,"Masih terdapat pilihan yang bisa dipilih, silahkan melengkapi pilihan "&"("&COUNTA(L13:P13)&"/"&Q13&")","")))) | Q13: =IFERROR(COUNTA(INDIRECT("K_"&MATCH(J13,BidangList,0))),0) -> 1
A14: =IF(F14="","",ROW()-5) | I14: =IF(AND(LEN(F14)=18, ISBLANK(G14)=FALSE(), ISBLANK(H14)=FALSE()),37,"") | K14: =IF(OR(J14="",Q14=0),"",IF(COUNTA(L14:P14)>Q14,"Seluruh pilihan telah dipilih, anda memilih lebih dari kemungkinan pilihan yang tersedia, periksa pilihan anda "&"("&COUNTA(L14:P14)&"/"&Q14&")",IF(COUNTA(L14:P14)=Q14,IF(SUMPRODUCT(COUNTIF(L14:P14,L14:P14)*(L14:P14<>""))>COUNTA(L14:P14),"Terdapat pilihan yang sama, segera ubah "&"("&COUNTA(L14:P14)&"/"&Q14&")","Seluruh pilihan telah dipilih "&"("&COUNTA(L14:P14)&"/"&Q14&")"),IF(COUNTA(L14:P14)>0,"Masih terdapat pilihan yang bisa dipilih, silahkan melengkapi pilihan "&"("&COUNTA(L14:P14)&"/"&Q14&")","")))) | Q14: =IFERROR(COUNTA(INDIRECT("K_"&MATCH(J14,BidangList,0))),0) -> 1
A15: =IF(F15="","",ROW()-5) | I15: =IF(AND(LEN(F15)=18, ISBLANK(G15)=FALSE(), ISBLANK(H15)=FALSE()),37,"") | K15: =IF(OR(J15="",Q15=0),"",IF(COUNTA(L15:P15)>Q15,"Seluruh pilihan telah dipilih, anda memilih lebih dari kemungkinan pilihan yang tersedia, periksa pilihan anda "&"("&COUNTA(L15:P15)&"/"&Q15&")",IF(COUNTA(L15:P15)=Q15,IF(SUMPRODUCT(COUNTIF(L15:P15,L15:P15)*(L15:P15<>""))>COUNTA(L15:P15),"Terdapat pilihan yang sama, segera ubah "&"("&COUNTA(L15:P15)&"/"&Q15&")","Seluruh pilihan telah dipilih "&"("&COUNTA(L15:P15)&"/"&Q15&")"),IF(COUNTA(L15:P15)>0,"Masih terdapat pilihan yang bisa dipilih, silahkan melengkapi pilihan "&"("&COUNTA(L15:P15)&"/"&Q15&")","")))) | Q15: =IFERROR(COUNTA(INDIRECT("K_"&MATCH(J15,BidangList,0))),0) -> 1
A16: =IF(F16="","",ROW()-5) | I16: =IF(AND(LEN(F16)=18, ISBLANK(G16)=FALSE(), ISBLANK(H16)=FALSE()),37,"") | K16: =IF(OR(J16="",Q16=0),"",IF(COUNTA(L16:P16)>Q16,"Seluruh pilihan telah dipilih, anda memilih lebih dari kemungkinan pilihan yang tersedia, periksa pilihan anda "&"("&COUNTA(L16:P16)&"/"&Q16&")",IF(COUNTA(L16:P16)=Q16,IF(SUMPRODUCT(COUNTIF(L16:P16,L16:P16)*(L16:P16<>""))>COUNTA(L16:P16),"Terdapat pilihan yang sama, segera ubah "&"("&COUNTA(L16:P16)&"/"&Q16&")","Seluruh pilihan telah dipilih "&"("&COUNTA(L16:P16)&"/"&Q16&")"),IF(COUNTA(L16:P16)>0,"Masih terdapat pilihan yang bisa dipilih, silahkan melengkapi pilihan "&"("&COUNTA(L16:P16)&"/"&Q16&")","")))) | Q16: =IFERROR(COUNTA(INDIRECT("K_"&MATCH(J16,BidangList,0))),0) -> 1
A17: =IF(F17="","",ROW()-5) | I17: =IF(AND(LEN(F17)=18, ISBLANK(G17)=FALSE(), ISBLANK(H17)=FALSE()),37,"") | K17: =IF(OR(J17="",Q17=0),"",IF(COUNTA(L17:P17)>Q17,"Seluruh pilihan telah dipilih, anda memilih lebih dari kemungkinan pilihan yang tersedia, periksa pilihan anda "&"("&COUNTA(L17:P17)&"/"&Q17&")",IF(COUNTA(L17:P17)=Q17,IF(SUMPRODUCT(COUNTIF(L17:P17,L17:P17)*(L17:P17<>""))>COUNTA(L17:P17),"Terdapat pilihan yang sama, segera ubah "&"("&COUNTA(L17:P17)&"/"&Q17&")","Seluruh pilihan telah dipilih "&"("&COUNTA(L17:P17)&"/"&Q17&")"),IF(COUNTA(L17:P17)>0,"Masih terdapat pilihan yang bisa dipilih, silahkan melengkapi pilihan "&"("&COUNTA(L17:P17)&"/"&Q17&")","")))) | Q17: =IFERROR(COUNTA(INDIRECT("K_"&MATCH(J17,BidangList,0))),0) -> 1
A18: =IF(F18="","",ROW()-5) | I18: =IF(AND(LEN(F18)=18, ISBLANK(G18)=FALSE(), ISBLANK(H18)=FALSE()),37,"") | K18: =IF(OR(J18="",Q18=0),"",IF(COUNTA(L18:P18)>Q18,"Seluruh pilihan telah dipilih, anda memilih lebih dari kemungkinan pilihan yang tersedia, periksa pilihan anda "&"("&COUNTA(L18:P18)&"/"&Q18&")",IF(COUNTA(L18:P18)=Q18,IF(SUMPRODUCT(COUNTIF(L18:P18,L18:P18)*(L18:P18<>""))>COUNTA(L18:P18),"Terdapat pilihan yang sama, segera ubah "&"("&COUNTA(L18:P18)&"/"&Q18&")","Seluruh pilihan telah dipilih "&"("&COUNTA(L18:P18)&"/"&Q18&")"),IF(COUNTA(L18:P18)>0,"Masih terdapat pilihan yang bisa dipilih, silahkan melengkapi pilihan "&"("&COUNTA(L18:P18)&"/"&Q18&")","")))) | Q18: =IFERROR(COUNTA(INDIRECT("K_"&MATCH(J18,BidangList,0))),0) -> 1
... A105: =IF(F105="","",ROW()-5) | I105: =IF(AND(LEN(F105)=18, ISBLANK(G105)=FALSE(), ISBLANK(H105)=FALSE()),37,"") | K105: =IF(OR(J105="",Q105=0),"",IF(COUNTA(L105:P105)>Q105,"Seluruh pilihan telah dipilih, anda memilih lebih dari kemungkinan pilihan yang tersedia, periksa pilihan anda "&"("&COUNTA(L105:P105)&"/"&Q105&")",IF(COUNTA(L105:P105)=Q105,IF(SUMPRODUCT(COUNTIF(L105:P105,L105:P105)*(L105:P105<>""))>COUNTA(L105:P105),"Terdapat pilihan yang sama, segera ubah "&"("&COUNTA(L105:P105)&"/"&Q105&")","Seluruh pilihan telah dipilih "&"("&COUNTA(L105:P105)&"/"&Q105&")"),IF(COUNTA(L105:P105)>0,"Masih terdapat pilihan yang bisa dipilih, silahkan melengkapi pilihan "&"("&COUNTA(L105:P105)&"/"&Q105&")","")))) | Q105: =IFERROR(COUNTA(INDIRECT("K_"&MATCH(J105,BidangList,0))),0) -> 1
A106: =IF(F106="","",ROW()-5) | I106: =IF(AND(LEN(F106)=18, ISBLANK(G106)=FALSE(), ISBLANK(H106)=FALSE()),37,"") | K106: =IF(OR(J106="",Q106=0),"",IF(COUNTA(L106:P106)>Q106,"Seluruh pilihan telah dipilih, anda memilih lebih dari kemungkinan pilihan yang tersedia, periksa pilihan anda "&"("&COUNTA(L106:P106)&"/"&Q106&")",IF(COUNTA(L106:P106)=Q106,IF(SUMPRODUCT(COUNTIF(L106:P106,L106:P106)*(L106:P106<>""))>COUNTA(L106:P106),"Terdapat pilihan yang sama, segera ubah "&"("&COUNTA(L106:P106)&"/"&Q106&")","Seluruh pilihan telah dipilih "&"("&COUNTA(L106:P106)&"/"&Q106&")"),IF(COUNTA(L106:P106)>0,"Masih terdapat pilihan yang bisa dipilih, silahkan melengkapi pilihan "&"("&COUNTA(L106:P106)&"/"&Q106&")",""))))
A107: =IF(F107="","",ROW()-5) | I107: =IF(AND(LEN(F107)=18, ISBLANK(G107)=FALSE(), ISBLANK(H107)=FALSE()),37,"") | K107: =IF(OR(J107="",Q107=0),"",IF(COUNTA(L107:P107)>Q107,"Seluruh pilihan telah dipilih, anda memilih lebih dari kemungkinan pilihan yang tersedia, periksa pilihan anda "&"("&COUNTA(L107:P107)&"/"&Q107&")",IF(COUNTA(L107:P107)=Q107,IF(SUMPRODUCT(COUNTIF(L107:P107,L107:P107)*(L107:P107<>""))>COUNTA(L107:P107),"Terdapat pilihan yang sama, segera ubah "&"("&COUNTA(L107:P107)&"/"&Q107&")","Seluruh pilihan telah dipilih "&"("&COUNTA(L107:P107)&"/"&Q107&")"),IF(COUNTA(L107:P107)>0,"Masih terdapat pilihan yang bisa dipilih, silahkan melengkapi pilihan "&"("&COUNTA(L107:P107)&"/"&Q107&")",""))))
A108: =IF(F108="","",ROW()-5) | I108: =IF(AND(LEN(F108)=18, ISBLANK(G108)=FALSE(), ISBLANK(H108)=FALSE()),37,"") | K108: =IF(OR(J108="",Q108=0),"",IF(COUNTA(L108:P108)>Q108,"Seluruh pilihan telah dipilih, anda memilih lebih dari kemungkinan pilihan yang tersedia, periksa pilihan anda "&"("&COUNTA(L108:P108)&"/"&Q108&")",IF(COUNTA(L108:P108)=Q108,IF(SUMPRODUCT(COUNTIF(L108:P108,L108:P108)*(L108:P108<>""))>COUNTA(L108:P108),"Terdapat pilihan yang sama, segera ubah "&"("&COUNTA(L108:P108)&"/"&Q108&")","Seluruh pilihan telah dipilih "&"("&COUNTA(L108:P108)&"/"&Q108&")"),IF(COUNTA(L108:P108)>0,"Masih terdapat pilihan yang bisa dipilih, silahkan melengkapi pilihan "&"("&COUNTA(L108:P108)&"/"&Q108&")",""))))
A109: =IF(F109="","",ROW()-5) | I109: =IF(AND(LEN(F109)=18, ISBLANK(G109)=FALSE(), ISBLANK(H109)=FALSE()),37,"") | K109: =IF(OR(J109="",Q109=0),"",IF(COUNTA(L109:P109)>Q109,"Seluruh pilihan telah dipilih, anda memilih lebih dari kemungkinan pilihan yang tersedia, periksa pilihan anda "&"("&COUNTA(L109:P109)&"/"&Q109&")",IF(COUNTA(L109:P109)=Q109,IF(SUMPRODUCT(COUNTIF(L109:P109,L109:P109)*(L109:P109<>""))>COUNTA(L109:P109),"Terdapat pilihan yang sama, segera ubah "&"("&COUNTA(L109:P109)&"/"&Q109&")","Seluruh pilihan telah dipilih "&"("&COUNTA(L109:P109)&"/"&Q109&")"),IF(COUNTA(L109:P109)>0,"Masih terdapat pilihan yang bisa dipilih, silahkan melengkapi pilihan "&"("&COUNTA(L109:P109)&"/"&Q109&")",""))))
A110: =IF(F110="","",ROW()-5) | I110: =IF(AND(LEN(F110)=18, ISBLANK(G110)=FALSE(), ISBLANK(H110)=FALSE()),37,"") | K110: =IF(OR(J110="",Q110=0),"",IF(COUNTA(L110:P110)>Q110,"Seluruh pilihan telah dipilih, anda memilih lebih dari kemungkinan pilihan yang tersedia, periksa pilihan anda "&"("&COUNTA(L110:P110)&"/"&Q110&")",IF(COUNTA(L110:P110)=Q110,IF(SUMPRODUCT(COUNTIF(L110:P110,L110:P110)*(L110:P110<>""))>COUNTA(L110:P110),"Terdapat pilihan yang sama, segera ubah "&"("&COUNTA(L110:P110)&"/"&Q110&")","Seluruh pilihan telah dipilih "&"("&COUNTA(L110:P110)&"/"&Q110&")"),IF(COUNTA(L110:P110)>0,"Masih terdapat pilihan yang bisa dipilih, silahkan melengkapi pilihan "&"("&COUNTA(L110:P110)&"/"&Q110&")",""))))
A111: =IF(F111="","",ROW()-5) | I111: =IF(AND(LEN(F111)=18, ISBLANK(G111)=FALSE(), ISBLANK(H111)=FALSE()),37,"") | K111: =IF(OR(J111="",Q111=0),"",IF(COUNTA(L111:P111)>Q111,"Seluruh pilihan telah dipilih, anda memilih lebih dari kemungkinan pilihan yang tersedia, periksa pilihan anda "&"("&COUNTA(L111:P111)&"/"&Q111&")",IF(COUNTA(L111:P111)=Q111,IF(SUMPRODUCT(COUNTIF(L111:P111,L111:P111)*(L111:P111<>""))>COUNTA(L111:P111),"Terdapat pilihan yang sama, segera ubah "&"("&COUNTA(L111:P111)&"/"&Q111&")","Seluruh pilihan telah dipilih "&"("&COUNTA(L111:P111)&"/"&Q111&")"),IF(COUNTA(L111:P111)>0,"Masih terdapat pilihan yang bisa dipilih, silahkan melengkapi pilihan "&"("&COUNTA(L111:P111)&"/"&Q111&")",""))))
A112: =IF(F112="","",ROW()-5) | I112: =IF(AND(LEN(F112)=18, ISBLANK(G112)=FALSE(), ISBLANK(H112)=FALSE()),37,"") | K112: =IF(OR(J112="",Q112=0),"",IF(COUNTA(L112:P112)>Q112,"Seluruh pilihan telah dipilih, anda memilih lebih dari kemungkinan pilihan yang tersedia, periksa pilihan anda "&"("&COUNTA(L112:P112)&"/"&Q112&")",IF(COUNTA(L112:P112)=Q112,IF(SUMPRODUCT(COUNTIF(L112:P112,L112:P112)*(L112:P112<>""))>COUNTA(L112:P112),"Terdapat pilihan yang sama, segera ubah "&"("&COUNTA(L112:P112)&"/"&Q112&")","Seluruh pilihan telah dipilih "&"("&COUNTA(L112:P112)&"/"&Q112&")"),IF(COUNTA(L112:P112)>0,"Masih terdapat pilihan yang bisa dipilih, silahkan melengkapi pilihan "&"("&COUNTA(L112:P112)&"/"&Q112&")",""))))
A113: =IF(F113="","",ROW()-5) | I113: =IF(AND(LEN(F113)=18, ISBLANK(G113)=FALSE(), ISBLANK(H113)=FALSE()),37,"") | K113: =IF(OR(J113="",Q113=0),"",IF(COUNTA(L113:P113)>Q113,"Seluruh pilihan telah dipilih, anda memilih lebih dari kemungkinan pilihan yang tersedia, periksa pilihan anda "&"("&COUNTA(L113:P113)&"/"&Q113&")",IF(COUNTA(L113:P113)=Q113,IF(SUMPRODUCT(COUNTIF(L113:P113,L113:P113)*(L113:P113<>""))>COUNTA(L113:P113),"Terdapat pilihan yang sama, segera ubah "&"("&COUNTA(L113:P113)&"/"&Q113&")","Seluruh pilihan telah dipilih "&"("&COUNTA(L113:P113)&"/"&Q113&")"),IF(COUNTA(L113:P113)>0,"Masih terdapat pilihan yang bisa dipilih, silahkan melengkapi pilihan "&"("&COUNTA(L113:P113)&"/"&Q113&")",""))))
A114: =IF(F114="","",ROW()-5) | I114: =IF(AND(LEN(F114)=18, ISBLANK(G114)=FALSE(), ISBLANK(H114)=FALSE()),37,"") | K114: =IF(OR(J114="",Q114=0),"",IF(COUNTA(L114:P114)>Q114,"Seluruh pilihan telah dipilih, anda memilih lebih dari kemungkinan pilihan yang tersedia, periksa pilihan anda "&"("&COUNTA(L114:P114)&"/"&Q114&")",IF(COUNTA(L114:P114)=Q114,IF(SUMPRODUCT(COUNTIF(L114:P114,L114:P114)*(L114:P114<>""))>COUNTA(L114:P114),"Terdapat pilihan yang sama, segera ubah "&"("&COUNTA(L114:P114)&"/"&Q114&")","Seluruh pilihan telah dipilih "&"("&COUNTA(L114:P114)&"/"&Q114&")"),IF(COUNTA(L114:P114)>0,"Masih terdapat pilihan yang bisa dipilih, silahkan melengkapi pilihan "&"("&COUNTA(L114:P114)&"/"&Q114&")",""))))
A115: =IF(F115="","",ROW()-5) | I115: =IF(AND(LEN(F115)=18, ISBLANK(G115)=FALSE(), ISBLANK(H115)=FALSE()),37,"") | K115: =IF(OR(J115="",Q115=0),"",IF(COUNTA(L115:P115)>Q115,"Seluruh pilihan telah dipilih, anda memilih lebih dari kemungkinan pilihan yang tersedia, periksa pilihan anda "&"("&COUNTA(L115:P115)&"/"&Q115&")",IF(COUNTA(L115:P115)=Q115,IF(SUMPRODUCT(COUNTIF(L115:P115,L115:P115)*(L115:P115<>""))>COUNTA(L115:P115),"Terdapat pilihan yang sama, segera ubah "&"("&COUNTA(L115:P115)&"/"&Q115&")","Seluruh pilihan telah dipilih "&"("&COUNTA(L115:P115)&"/"&Q115&")"),IF(COUNTA(L115:P115)>0,"Masih terdapat pilihan yang bisa dipilih, silahkan melengkapi pilihan "&"("&COUNTA(L115:P115)&"/"&Q115&")",""))))
A116: =IF(F116="","",ROW()-5) | I116: =IF(AND(LEN(F116)=18, ISBLANK(G116)=FALSE(), ISBLANK(H116)=FALSE()),37,"") | K116: =IF(OR(J116="",Q116=0),"",IF(COUNTA(L116:P116)>Q116,"Seluruh pilihan telah dipilih, anda memilih lebih dari kemungkinan pilihan yang tersedia, periksa pilihan anda "&"("&COUNTA(L116:P116)&"/"&Q116&")",IF(COUNTA(L116:P116)=Q116,IF(SUMPRODUCT(COUNTIF(L116:P116,L116:P116)*(L116:P116<>""))>COUNTA(L116:P116),"Terdapat pilihan yang sama, segera ubah "&"("&COUNTA(L116:P116)&"/"&Q116&")","Seluruh pilihan telah dipilih "&"("&COUNTA(L116:P116)&"/"&Q116&")"),IF(COUNTA(L116:P116)>0,"Masih terdapat pilihan yang bisa dipilih, silahkan melengkapi pilihan "&"("&COUNTA(L116:P116)&"/"&Q116&")",""))))
A117: =IF(F117="","",ROW()-5) | I117: =IF(AND(LEN(F117)=18, ISBLANK(G117)=FALSE(), ISBLANK(H117)=FALSE()),37,"") | K117: =IF(OR(J117="",Q117=0),"",IF(COUNTA(L117:P117)>Q117,"Seluruh pilihan telah dipilih, anda memilih lebih dari kemungkinan pilihan yang tersedia, periksa pilihan anda "&"("&COUNTA(L117:P117)&"/"&Q117&")",IF(COUNTA(L117:P117)=Q117,IF(SUMPRODUCT(COUNTIF(L117:P117,L117:P117)*(L117:P117<>""))>COUNTA(L117:P117),"Terdapat pilihan yang sama, segera ubah "&"("&COUNTA(L117:P117)&"/"&Q117&")","Seluruh pilihan telah dipilih "&"("&COUNTA(L117:P117)&"/"&Q117&")"),IF(COUNTA(L117:P117)>0,"Masih terdapat pilihan yang bisa dipilih, silahkan melengkapi pilihan "&"("&COUNTA(L117:P117)&"/"&Q117&")",""))))
... A1005: =IF(F1005="","",ROW()-5) | I1005: =IF(AND(LEN(F1005)=18, ISBLANK(G1005)=FALSE(), ISBLANK(H1005)=FALSE()),37,"") | K1005: =IF(OR(J1005="",Q1005=0),"",IF(COUNTA(L1005:P1005)>Q1005,"Seluruh pilihan telah dipilih, anda memilih lebih dari kemungkinan pilihan yang tersedia, periksa pilihan anda "&"("&COUNTA(L1005:P1005)&"/"&Q1005&")",IF(COUNTA(L1005:P1005)=Q1005,IF(SUMPRODUCT(COUNTIF(L1005:P1005,L1005:P1005)*(L1005:P1005<>""))>COUNTA(L1005:P1005),"Terdapat pilihan yang sama, segera ubah "&"("&COUNTA(L1005:P1005)&"/"&Q1005&")","Seluruh pilihan telah dipilih "&"("&COUNTA(L1005:P1005)&"/"&Q1005&")"),IF(COUNTA(L1005:P1005)>0,"Masih terdapat pilihan yang bisa dipilih, silahkan melengkapi pilihan "&"("&COUNTA(L1005:P1005)&"/"&Q1005&")",""))))

Sheet INPUT
A1: No | B1: JALUR | C1: NIP | D1: NAMA | E1: EMAIL | F1: ID INSTANSI | G1: ASAL PRODI | H1: Prioritas Prodi 1 | I1: Prioritas Prodi 2 | J1: Prioritas Prodi 3 | K1: Prioritas Prodi 4 | L1: Prioritas Prodi 5
A2: =IF(C2="","",ROW()-1) | B2: {=IFERROR(INDEX(checklistPesertaKemenkeu!$E$6:$E$1005,SMALL(IF(checklistPesertaKemenkeu!$AY$6:$AY$1005="Direkomendasikan",ROW($6:$1005)-5),ROW()-1)),"")} | C2: {=IFERROR(INDEX(checklistPesertaKemenkeu!$F$6:$F$1005,SMALL(IF(checklistPesertaKemenkeu!$AY$6:$AY$1005="Direkomendasikan",ROW($6:$1005)-5),1)),"")} | D2: {=IFERROR(INDEX(checklistPesertaKemenkeu!$G$6:$G$1005,SMALL(IF(checklistPesertaKemenkeu!$AY$6:$AY$1005="Direkomendasikan",ROW($6:$1005)-5),1)),"")} | E2: {=IFERROR(INDEX(checklistPesertaKemenkeu!$H$6:$H$1005,SMALL(IF(checklistPesertaKemenkeu!$AY$6:$AY$1005="Direkomendasikan",ROW($6:$1005)-5),1)),"")} | F2: {=IFERROR(INDEX(checklistPesertaKemenkeu!$I$6:$I$1005,SMALL(IF(checklistPesertaKemenkeu!$AY$6:$AY$1005="Direkomendasikan",ROW($6:$1005)-5),1)),"")} | G2: {=IFERROR(INDEX(checklistPesertaKemenkeu!$J$6:$J$1005,SMALL(IF(checklistPesertaKemenkeu!$AY$6:$AY$1005="Direkomendasikan",ROW($6:$1005)-5),1)),"")} | H2: {=IFERROR(IF(OR(INDEX(checklistPesertaKemenkeu!$L$6:$L$1005,SMALL(IF(checklistPesertaKemenkeu!$AY$6:$AY$1005="Direkomendasikan",ROW($6:$1005)-5),1))="",INDEX(checklistPesertaKemenkeu!$J$6:$J$1005,SMALL(IF(checklistPesertaKemenkeu!$AY$6:$AY$1005="Direkomendasikan",ROW($6:$1005)-5),1))=""),"",IF(AND(COUNTIF(INDIRECT("K_"&MATCH(INDEX(checklistPesertaKemenkeu!$J$6:$J$1005,SMALL(IF(checklistPesertaKemenkeu!$AY$6:$AY$1005="Direkomendasikan",ROW($6:$1005)-5),1)),BidangList,0)),INDEX(checklistPesertaKemenkeu!$L$6:$L$1005,SMALL(IF(checklistPesertaKemenkeu!$AY$6:$AY$1005="Direkomendasikan",ROW($6:$1005)-5),1)))>0,COUNTIF(INDIRECT("'KERTAS KERJA'!K"&(SMALL(IF(checklistPesertaKemenkeu!$AY$6:$AY$1005="Direkomendasikan",ROW($6:$1005)-5),1)+5)&":O"&(SMALL(IF(checklistPesertaKemenkeu!$AY$6:$AY$1005="Direkomendasikan",ROW($6:$1005)-5),1)+5)),INDEX(checklistPesertaKemenkeu!$L$6:$L$1005,SMALL(IF(checklistPesertaKemenkeu!$AY$6:$AY$1005="Direkomendasikan",ROW($6:$1005)-5),1)))=1),IFERROR(VLOOKUP(INDEX(checklistPesertaKemenkeu!$L$6:$L$1005,SMALL(IF(checklistPesertaKemenkeu!$AY$6:$AY$1005="Direkomendasikan",ROW($6:$1005)-5),1)),KotaKode,2,0),"-"),"")),"")} | I2: {=IFERROR(IF(OR(INDEX(checklistPesertaKemenkeu!$M$6:$M$1005,SMALL(IF(checklistPesertaKemenkeu!$AY$6:$AY$1005="Direkomendasikan",ROW($6:$1005)-5),1))="",INDEX(checklistPesertaKemenkeu!$J$6:$J$1005,SMALL(IF(checklistPesertaKemenkeu!$AY$6:$AY$1005="Direkomendasikan",ROW($6:$1005)-5),1))=""),"",IF(AND(COUNTIF(INDIRECT("K_"&MATCH(INDEX(checklistPesertaKemenkeu!$J$6:$J$1005,SMALL(IF(checklistPesertaKemenkeu!$AY$6:$AY$1005="Direkomendasikan",ROW($6:$1005)-5),1)),BidangList,0)),INDEX(checklistPesertaKemenkeu!$M$6:$M$1005,SMALL(IF(checklistPesertaKemenkeu!$AY$6:$AY$1005="Direkomendasikan",ROW($6:$1005)-5),1)))>0,COUNTIF(INDIRECT("'KERTAS KERJA'!K"&(SMALL(IF(checklistPesertaKemenkeu!$AY$6:$AY$1005="Direkomendasikan",ROW($6:$1005)-5),1)+5)&":O"&(SMALL(IF(checklistPesertaKemenkeu!$AY$6:$AY$1005="Direkomendasikan",ROW($6:$1005)-5),1)+5)),INDEX(checklistPesertaKemenkeu!$M$6:$M$1005,SMALL(IF(checklistPesertaKemenkeu!$AY$6:$AY$1005="Direkomendasikan",ROW($6:$1005)-5),1)))=1),IFERROR(VLOOKUP(INDEX(checklistPesertaKemenkeu!$M$6:$M$1005,SMALL(IF(checklistPesertaKemenkeu!$AY$6:$AY$1005="Direkomendasikan",ROW($6:$1005)-5),1)),KotaKode,2,0),"-"),"")),"")} | J2: {=IFERROR(IF(OR(INDEX(checklistPesertaKemenkeu!$N$6:$N$1005,SMALL(IF(checklistPesertaKemenkeu!$AY$6:$AY$1005="Direkomendasikan",ROW($6:$1005)-5),1))="",INDEX(checklistPesertaKemenkeu!$J$6:$J$1005,SMALL(IF(checklistPesertaKemenkeu!$AY$6:$AY$1005="Direkomendasikan",ROW($6:$1005)-5),1))=""),"",IF(AND(COUNTIF(INDIRECT("K_"&MATCH(INDEX(checklistPesertaKemenkeu!$J$6:$J$1005,SMALL(IF(checklistPesertaKemenkeu!$AY$6:$AY$1005="Direkomendasikan",ROW($6:$1005)-5),1)),BidangList,0)),INDEX(checklistPesertaKemenkeu!$N$6:$N$1005,SMALL(IF(checklistPesertaKemenkeu!$AY$6:$AY$1005="Direkomendasikan",ROW($6:$1005)-5),1)))>0,COUNTIF(INDIRECT("'KERTAS KERJA'!K"&(SMALL(IF(checklistPesertaKemenkeu!$AY$6:$AY$1005="Direkomendasikan",ROW($6:$1005)-5),1)+5)&":O"&(SMALL(IF(checklistPesertaKemenkeu!$AY$6:$AY$1005="Direkomendasikan",ROW($6:$1005)-5),1)+5)),INDEX(checklistPesertaKemenkeu!$N$6:$N$1005,SMALL(IF(checklistPesertaKemenkeu!$AY$6:$AY$1005="Direkomendasikan",ROW($6:$1005)-5),1)))=1),IFERROR(VLOOKUP(INDEX(checklistPesertaKemenkeu!$N$6:$N$1005,SMALL(IF(checklistPesertaKemenkeu!$AY$6:$AY$1005="Direkomendasikan",ROW($6:$1005)-5),1)),KotaKode,2,0),"-"),"")),"")} | K2: {=IFERROR(IF(OR(INDEX(checklistPesertaKemenkeu!$O$6:$O$1005,SMALL(IF(checklistPesertaKemenkeu!$AY$6:$AY$1005="Direkomendasikan",ROW($6:$1005)-5),1))="",INDEX(checklistPesertaKemenkeu!$J$6:$J$1005,SMALL(IF(checklistPesertaKemenkeu!$AY$6:$AY$1005="Direkomendasikan",ROW($6:$1005)-5),1))=""),"",IF(AND(COUNTIF(INDIRECT("K_"&MATCH(INDEX(checklistPesertaKemenkeu!$J$6:$J$1005,SMALL(IF(checklistPesertaKemenkeu!$AY$6:$AY$1005="Direkomendasikan",ROW($6:$1005)-5),1)),BidangList,0)),INDEX(checklistPesertaKemenkeu!$O$6:$O$1005,SMALL(IF(checklistPesertaKemenkeu!$AY$6:$AY$1005="Direkomendasikan",ROW($6:$1005)-5),1)))>0,COUNTIF(INDIRECT("'KERTAS KERJA'!K"&(SMALL(IF(checklistPesertaKemenkeu!$AY$6:$AY$1005="Direkomendasikan",ROW($6:$1005)-5),1)+5)&":O"&(SMALL(IF(checklistPesertaKemenkeu!$AY$6:$AY$1005="Direkomendasikan",ROW($6:$1005)-5),1)+5)),INDEX(checklistPesertaKemenkeu!$O$6:$O$1005,SMALL(IF(checklistPesertaKemenkeu!$AY$6:$AY$1005="Direkomendasikan",ROW($6:$1005)-5),1)))=1),IFERROR(VLOOKUP(INDEX(checklistPesertaKemenkeu!$O$6:$O$1005,SMALL(IF(checklistPesertaKemenkeu!$AY$6:$AY$1005="Direkomendasikan",ROW($6:$1005)-5),1)),KotaKode,2,0),"-"),"")),"")} | L2: {=IFERROR(IF(OR(INDEX(checklistPesertaKemenkeu!$P$6:$P$1005,SMALL(IF(checklistPesertaKemenkeu!$AY$6:$AY$1005="Direkomendasikan",ROW($6:$1005)-5),1))="",INDEX(checklistPesertaKemenkeu!$J$6:$J$1005,SMALL(IF(checklistPesertaKemenkeu!$AY$6:$AY$1005="Direkomendasikan",ROW($6:$1005)-5),1))=""),"",IF(AND(COUNTIF(INDIRECT("K_"&MATCH(INDEX(checklistPesertaKemenkeu!$J$6:$J$1005,SMALL(IF(checklistPesertaKemenkeu!$AY$6:$AY$1005="Direkomendasikan",ROW($6:$1005)-5),1)),BidangList,0)),INDEX(checklistPesertaKemenkeu!$P$6:$P$1005,SMALL(IF(checklistPesertaKemenkeu!$AY$6:$AY$1005="Direkomendasikan",ROW($6:$1005)-5),1)))>0,COUNTIF(INDIRECT("'KERTAS KERJA'!K"&(SMALL(IF(checklistPesertaKemenkeu!$AY$6:$AY$1005="Direkomendasikan",ROW($6:$1005)-5),1)+5)&":O"&(SMALL(IF(checklistPesertaKemenkeu!$AY$6:$AY$1005="Direkomendasikan",ROW($6:$1005)-5),1)+5)),INDEX(checklistPesertaKemenkeu!$P$6:$P$1005,SMALL(IF(checklistPesertaKemenkeu!$AY$6:$AY$1005="Direkomendasikan",ROW($6:$1005)-5),1)))=1),IFERROR(VLOOKUP(INDEX(checklistPesertaKemenkeu!$P$6:$P$1005,SMALL(IF(checklistPesertaKemenkeu!$AY$6:$AY$1005="Direkomendasikan",ROW($6:$1005)-5),1)),KotaKode,2,0),"-"),"")),"")}
A3: =IF(C3="","",ROW()-1) | C3: {=IFERROR(INDEX(checklistPesertaKemenkeu!$F$6:$F$1005,SMALL(IF(checklistPesertaKemenkeu!$AY$6:$AY$1005="Direkomendasikan",ROW($6:$1005)-5),2)),"")} | D3: {=IFERROR(INDEX(checklistPesertaKemenkeu!$G$6:$G$1005,SMALL(IF(checklistPesertaKemenkeu!$AY$6:$AY$1005="Direkomendasikan",ROW($6:$1005)-5),2)),"")} | E3: {=IFERROR(INDEX(checklistPesertaKemenkeu!$H$6:$H$1005,SMALL(IF(checklistPesertaKemenkeu!$AY$6:$AY$1005="Direkomendasikan",ROW($6:$1005)-5),2)),"")} | F3: {=IFERROR(INDEX(checklistPesertaKemenkeu!$I$6:$I$1005,SMALL(IF(checklistPesertaKemenkeu!$AY$6:$AY$1005="Direkomendasikan",ROW($6:$1005)-5),2)),"")} | G3: {=IFERROR(INDEX(checklistPesertaKemenkeu!$J$6:$J$1005,SMALL(IF(checklistPesertaKemenkeu!$AY$6:$AY$1005="Direkomendasikan",ROW($6:$1005)-5),2)),"")} | H3: {=IFERROR(IF(OR(INDEX(checklistPesertaKemenkeu!$L$6:$L$1005,SMALL(IF(checklistPesertaKemenkeu!$AY$6:$AY$1005="Direkomendasikan",ROW($6:$1005)-5),2))="",INDEX(checklistPesertaKemenkeu!$J$6:$J$1005,SMALL(IF(checklistPesertaKemenkeu!$AY$6:$AY$1005="Direkomendasikan",ROW($6:$1005)-5),2))=""),"",IF(AND(COUNTIF(INDIRECT("K_"&MATCH(INDEX(checklistPesertaKemenkeu!$J$6:$J$1005,SMALL(IF(checklistPesertaKemenkeu!$AY$6:$AY$1005="Direkomendasikan",ROW($6:$1005)-5),2)),BidangList,0)),INDEX(checklistPesertaKemenkeu!$L$6:$L$1005,SMALL(IF(checklistPesertaKemenkeu!$AY$6:$AY$1005="Direkomendasikan",ROW($6:$1005)-5),2)))>0,COUNTIF(INDIRECT("'KERTAS KERJA'!K"&(SMALL(IF(checklistPesertaKemenkeu!$AY$6:$AY$1005="Direkomendasikan",ROW($6:$1005)-5),2)+5)&":O"&(SMALL(IF(checklistPesertaKemenkeu!$AY$6:$AY$1005="Direkomendasikan",ROW($6:$1005)-5),2)+5)),INDEX(checklistPesertaKemenkeu!$L$6:$L$1005,SMALL(IF(checklistPesertaKemenkeu!$AY$6:$AY$1005="Direkomendasikan",ROW($6:$1005)-5),2)))=1),IFERROR(VLOOKUP(INDEX(checklistPesertaKemenkeu!$L$6:$L$1005,SMALL(IF(checklistPesertaKemenkeu!$AY$6:$AY$1005="Direkomendasikan",ROW($6:$1005)-5),2)),KotaKode,2,0),"-"),"")),"")} | I3: {=IFERROR(IF(OR(INDEX(checklistPesertaKemenkeu!$M$6:$M$1005,SMALL(IF(checklistPesertaKemenkeu!$AY$6:$AY$1005="Direkomendasikan",ROW($6:$1005)-5),2))="",INDEX(checklistPesertaKemenkeu!$J$6:$J$1005,SMALL(IF(checklistPesertaKemenkeu!$AY$6:$AY$1005="Direkomendasikan",ROW($6:$1005)-5),2))=""),"",IF(AND(COUNTIF(INDIRECT("K_"&MATCH(INDEX(checklistPesertaKemenkeu!$J$6:$J$1005,SMALL(IF(checklistPesertaKemenkeu!$AY$6:$AY$1005="Direkomendasikan",ROW($6:$1005)-5),2)),BidangList,0)),INDEX(checklistPesertaKemenkeu!$M$6:$M$1005,SMALL(IF(checklistPesertaKemenkeu!$AY$6:$AY$1005="Direkomendasikan",ROW($6:$1005)-5),2)))>0,COUNTIF(INDIRECT("'KERTAS KERJA'!K"&(SMALL(IF(checklistPesertaKemenkeu!$AY$6:$AY$1005="Direkomendasikan",ROW($6:$1005)-5),2)+5)&":O"&(SMALL(IF(checklistPesertaKemenkeu!$AY$6:$AY$1005="Direkomendasikan",ROW($6:$1005)-5),2)+5)),INDEX(checklistPesertaKemenkeu!$M$6:$M$1005,SMALL(IF(checklistPesertaKemenkeu!$AY$6:$AY$1005="Direkomendasikan",ROW($6:$1005)-5),2)))=1),IFERROR(VLOOKUP(INDEX(checklistPesertaKemenkeu!$M$6:$M$1005,SMALL(IF(checklistPesertaKemenkeu!$AY$6:$AY$1005="Direkomendasikan",ROW($6:$1005)-5),2)),KotaKode,2,0),"-"),"")),"")} | J3: {=IFERROR(IF(OR(INDEX(checklistPesertaKemenkeu!$N$6:$N$1005,SMALL(IF(checklistPesertaKemenkeu!$AY$6:$AY$1005="Direkomendasikan",ROW($6:$1005)-5),2))="",INDEX(checklistPesertaKemenkeu!$J$6:$J$1005,SMALL(IF(checklistPesertaKemenkeu!$AY$6:$AY$1005="Direkomendasikan",ROW($6:$1005)-5),2))=""),"",IF(AND(COUNTIF(INDIRECT("K_"&MATCH(INDEX(checklistPesertaKemenkeu!$J$6:$J$1005,SMALL(IF(checklistPesertaKemenkeu!$AY$6:$AY$1005="Direkomendasikan",ROW($6:$1005)-5),2)),BidangList,0)),INDEX(checklistPesertaKemenkeu!$N$6:$N$1005,SMALL(IF(checklistPesertaKemenkeu!$AY$6:$AY$1005="Direkomendasikan",ROW($6:$1005)-5),2)))>0,COUNTIF(INDIRECT("'KERTAS KERJA'!K"&(SMALL(IF(checklistPesertaKemenkeu!$AY$6:$AY$1005="Direkomendasikan",ROW($6:$1005)-5),2)+5)&":O"&(SMALL(IF(checklistPesertaKemenkeu!$AY$6:$AY$1005="Direkomendasikan",ROW($6:$1005)-5),2)+5)),INDEX(checklistPesertaKemenkeu!$N$6:$N$1005,SMALL(IF(checklistPesertaKemenkeu!$AY$6:$AY$1005="Direkomendasikan",ROW($6:$1005)-5),2)))=1),IFERROR(VLOOKUP(INDEX(checklistPesertaKemenkeu!$N$6:$N$1005,SMALL(IF(checklistPesertaKemenkeu!$AY$6:$AY$1005="Direkomendasikan",ROW($6:$1005)-5),2)),KotaKode,2,0),"-"),"")),"")} | K3: {=IFERROR(IF(OR(INDEX(checklistPesertaKemenkeu!$O$6:$O$1005,SMALL(IF(checklistPesertaKemenkeu!$AY$6:$AY$1005="Direkomendasikan",ROW($6:$1005)-5),2))="",INDEX(checklistPesertaKemenkeu!$J$6:$J$1005,SMALL(IF(checklistPesertaKemenkeu!$AY$6:$AY$1005="Direkomendasikan",ROW($6:$1005)-5),2))=""),"",IF(AND(COUNTIF(INDIRECT("K_"&MATCH(INDEX(checklistPesertaKemenkeu!$J$6:$J$1005,SMALL(IF(checklistPesertaKemenkeu!$AY$6:$AY$1005="Direkomendasikan",ROW($6:$1005)-5),2)),BidangList,0)),INDEX(checklistPesertaKemenkeu!$O$6:$O$1005,SMALL(IF(checklistPesertaKemenkeu!$AY$6:$AY$1005="Direkomendasikan",ROW($6:$1005)-5),2)))>0,COUNTIF(INDIRECT("'KERTAS KERJA'!K"&(SMALL(IF(checklistPesertaKemenkeu!$AY$6:$AY$1005="Direkomendasikan",ROW($6:$1005)-5),2)+5)&":O"&(SMALL(IF(checklistPesertaKemenkeu!$AY$6:$AY$1005="Direkomendasikan",ROW($6:$1005)-5),2)+5)),INDEX(checklistPesertaKemenkeu!$O$6:$O$1005,SMALL(IF(checklistPesertaKemenkeu!$AY$6:$AY$1005="Direkomendasikan",ROW($6:$1005)-5),2)))=1),IFERROR(VLOOKUP(INDEX(checklistPesertaKemenkeu!$O$6:$O$1005,SMALL(IF(checklistPesertaKemenkeu!$AY$6:$AY$1005="Direkomendasikan",ROW($6:$1005)-5),2)),KotaKode,2,0),"-"),"")),"")} | L3: {=IFERROR(IF(OR(INDEX(checklistPesertaKemenkeu!$P$6:$P$1005,SMALL(IF(checklistPesertaKemenkeu!$AY$6:$AY$1005="Direkomendasikan",ROW($6:$1005)-5),2))="",INDEX(checklistPesertaKemenkeu!$J$6:$J$1005,SMALL(IF(checklistPesertaKemenkeu!$AY$6:$AY$1005="Direkomendasikan",ROW($6:$1005)-5),2))=""),"",IF(AND(COUNTIF(INDIRECT("K_"&MATCH(INDEX(checklistPesertaKemenkeu!$J$6:$J$1005,SMALL(IF(checklistPesertaKemenkeu!$AY$6:$AY$1005="Direkomendasikan",ROW($6:$1005)-5),2)),BidangList,0)),INDEX(checklistPesertaKemenkeu!$P$6:$P$1005,SMALL(IF(checklistPesertaKemenkeu!$AY$6:$AY$1005="Direkomendasikan",ROW($6:$1005)-5),2)))>0,COUNTIF(INDIRECT("'KERTAS KERJA'!K"&(SMALL(IF(checklistPesertaKemenkeu!$AY$6:$AY$1005="Direkomendasikan",ROW($6:$1005)-5),2)+5)&":O"&(SMALL(IF(checklistPesertaKemenkeu!$AY$6:$AY$1005="Direkomendasikan",ROW($6:$1005)-5),2)+5)),INDEX(checklistPesertaKemenkeu!$P$6:$P$1005,SMALL(IF(checklistPesertaKemenkeu!$AY$6:$AY$1005="Direkomendasikan",ROW($6:$1005)-5),2)))=1),IFERROR(VLOOKUP(INDEX(checklistPesertaKemenkeu!$P$6:$P$1005,SMALL(IF(checklistPesertaKemenkeu!$AY$6:$AY$1005="Direkomendasikan",ROW($6:$1005)-5),2)),KotaKode,2,0),"-"),"")),"")}
A4: =IF(C4="","",ROW()-1) | C4: {=IFERROR(INDEX(checklistPesertaKemenkeu!$F$6:$F$1005,SMALL(IF(checklistPesertaKemenkeu!$AY$6:$AY$1005="Direkomendasikan",ROW($6:$1005)-5),3)),"")} | D4: {=IFERROR(INDEX(checklistPesertaKemenkeu!$G$6:$G$1005,SMALL(IF(checklistPesertaKemenkeu!$AY$6:$AY$1005="Direkomendasikan",ROW($6:$1005)-5),3)),"")} | E4: {=IFERROR(INDEX(checklistPesertaKemenkeu!$H$6:$H$1005,SMALL(IF(checklistPesertaKemenkeu!$AY$6:$AY$1005="Direkomendasikan",ROW($6:$1005)-5),3)),"")} | F4: {=IFERROR(INDEX(checklistPesertaKemenkeu!$I$6:$I$1005,SMALL(IF(checklistPesertaKemenkeu!$AY$6:$AY$1005="Direkomendasikan",ROW($6:$1005)-5),3)),"")} | G4: {=IFERROR(INDEX(checklistPesertaKemenkeu!$J$6:$J$1005,SMALL(IF(checklistPesertaKemenkeu!$AY$6:$AY$1005="Direkomendasikan",ROW($6:$1005)-5),3)),"")} | H4: {=IFERROR(IF(OR(INDEX(checklistPesertaKemenkeu!$L$6:$L$1005,SMALL(IF(checklistPesertaKemenkeu!$AY$6:$AY$1005="Direkomendasikan",ROW($6:$1005)-5),3))="",INDEX(checklistPesertaKemenkeu!$J$6:$J$1005,SMALL(IF(checklistPesertaKemenkeu!$AY$6:$AY$1005="Direkomendasikan",ROW($6:$1005)-5),3))=""),"",IF(AND(COUNTIF(INDIRECT("K_"&MATCH(INDEX(checklistPesertaKemenkeu!$J$6:$J$1005,SMALL(IF(checklistPesertaKemenkeu!$AY$6:$AY$1005="Direkomendasikan",ROW($6:$1005)-5),3)),BidangList,0)),INDEX(checklistPesertaKemenkeu!$L$6:$L$1005,SMALL(IF(checklistPesertaKemenkeu!$AY$6:$AY$1005="Direkomendasikan",ROW($6:$1005)-5),3)))>0,COUNTIF(INDIRECT("'KERTAS KERJA'!K"&(SMALL(IF(checklistPesertaKemenkeu!$AY$6:$AY$1005="Direkomendasikan",ROW($6:$1005)-5),3)+5)&":O"&(SMALL(IF(checklistPesertaKemenkeu!$AY$6:$AY$1005="Direkomendasikan",ROW($6:$1005)-5),3)+5)),INDEX(checklistPesertaKemenkeu!$L$6:$L$1005,SMALL(IF(checklistPesertaKemenkeu!$AY$6:$AY$1005="Direkomendasikan",ROW($6:$1005)-5),3)))=1),IFERROR(VLOOKUP(INDEX(checklistPesertaKemenkeu!$L$6:$L$1005,SMALL(IF(checklistPesertaKemenkeu!$AY$6:$AY$1005="Direkomendasikan",ROW($6:$1005)-5),3)),KotaKode,2,0),"-"),"")),"")} | I4: {=IFERROR(IF(OR(INDEX(checklistPesertaKemenkeu!$M$6:$M$1005,SMALL(IF(checklistPesertaKemenkeu!$AY$6:$AY$1005="Direkomendasikan",ROW($6:$1005)-5),3))="",INDEX(checklistPesertaKemenkeu!$J$6:$J$1005,SMALL(IF(checklistPesertaKemenkeu!$AY$6:$AY$1005="Direkomendasikan",ROW($6:$1005)-5),3))=""),"",IF(AND(COUNTIF(INDIRECT("K_"&MATCH(INDEX(checklistPesertaKemenkeu!$J$6:$J$1005,SMALL(IF(checklistPesertaKemenkeu!$AY$6:$AY$1005="Direkomendasikan",ROW($6:$1005)-5),3)),BidangList,0)),INDEX(checklistPesertaKemenkeu!$M$6:$M$1005,SMALL(IF(checklistPesertaKemenkeu!$AY$6:$AY$1005="Direkomendasikan",ROW($6:$1005)-5),3)))>0,COUNTIF(INDIRECT("'KERTAS KERJA'!K"&(SMALL(IF(checklistPesertaKemenkeu!$AY$6:$AY$1005="Direkomendasikan",ROW($6:$1005)-5),3)+5)&":O"&(SMALL(IF(checklistPesertaKemenkeu!$AY$6:$AY$1005="Direkomendasikan",ROW($6:$1005)-5),3)+5)),INDEX(checklistPesertaKemenkeu!$M$6:$M$1005,SMALL(IF(checklistPesertaKemenkeu!$AY$6:$AY$1005="Direkomendasikan",ROW($6:$1005)-5),3)))=1),IFERROR(VLOOKUP(INDEX(checklistPesertaKemenkeu!$M$6:$M$1005,SMALL(IF(checklistPesertaKemenkeu!$AY$6:$AY$1005="Direkomendasikan",ROW($6:$1005)-5),3)),KotaKode,2,0),"-"),"")),"")} | J4: {=IFERROR(IF(OR(INDEX(checklistPesertaKemenkeu!$N$6:$N$1005,SMALL(IF(checklistPesertaKemenkeu!$AY$6:$AY$1005="Direkomendasikan",ROW($6:$1005)-5),3))="",INDEX(checklistPesertaKemenkeu!$J$6:$J$1005,SMALL(IF(checklistPesertaKemenkeu!$AY$6:$AY$1005="Direkomendasikan",ROW($6:$1005)-5),3))=""),"",IF(AND(COUNTIF(INDIRECT("K_"&MATCH(INDEX(checklistPesertaKemenkeu!$J$6:$J$1005,SMALL(IF(checklistPesertaKemenkeu!$AY$6:$AY$1005="Direkomendasikan",ROW($6:$1005)-5),3)),BidangList,0)),INDEX(checklistPesertaKemenkeu!$N$6:$N$1005,SMALL(IF(checklistPesertaKemenkeu!$AY$6:$AY$1005="Direkomendasikan",ROW($6:$1005)-5),3)))>0,COUNTIF(INDIRECT("'KERTAS KERJA'!K"&(SMALL(IF(checklistPesertaKemenkeu!$AY$6:$AY$1005="Direkomendasikan",ROW($6:$1005)-5),3)+5)&":O"&(SMALL(IF(checklistPesertaKemenkeu!$AY$6:$AY$1005="Direkomendasikan",ROW($6:$1005)-5),3)+5)),INDEX(checklistPesertaKemenkeu!$N$6:$N$1005,SMALL(IF(checklistPesertaKemenkeu!$AY$6:$AY$1005="Direkomendasikan",ROW($6:$1005)-5),3)))=1),IFERROR(VLOOKUP(INDEX(checklistPesertaKemenkeu!$N$6:$N$1005,SMALL(IF(checklistPesertaKemenkeu!$AY$6:$AY$1005="Direkomendasikan",ROW($6:$1005)-5),3)),KotaKode,2,0),"-"),"")),"")} | K4: {=IFERROR(IF(OR(INDEX(checklistPesertaKemenkeu!$O$6:$O$1005,SMALL(IF(checklistPesertaKemenkeu!$AY$6:$AY$1005="Direkomendasikan",ROW($6:$1005)-5),3))="",INDEX(checklistPesertaKemenkeu!$J$6:$J$1005,SMALL(IF(checklistPesertaKemenkeu!$AY$6:$AY$1005="Direkomendasikan",ROW($6:$1005)-5),3))=""),"",IF(AND(COUNTIF(INDIRECT("K_"&MATCH(INDEX(checklistPesertaKemenkeu!$J$6:$J$1005,SMALL(IF(checklistPesertaKemenkeu!$AY$6:$AY$1005="Direkomendasikan",ROW($6:$1005)-5),3)),BidangList,0)),INDEX(checklistPesertaKemenkeu!$O$6:$O$1005,SMALL(IF(checklistPesertaKemenkeu!$AY$6:$AY$1005="Direkomendasikan",ROW($6:$1005)-5),3)))>0,COUNTIF(INDIRECT("'KERTAS KERJA'!K"&(SMALL(IF(checklistPesertaKemenkeu!$AY$6:$AY$1005="Direkomendasikan",ROW($6:$1005)-5),3)+5)&":O"&(SMALL(IF(checklistPesertaKemenkeu!$AY$6:$AY$1005="Direkomendasikan",ROW($6:$1005)-5),3)+5)),INDEX(checklistPesertaKemenkeu!$O$6:$O$1005,SMALL(IF(checklistPesertaKemenkeu!$AY$6:$AY$1005="Direkomendasikan",ROW($6:$1005)-5),3)))=1),IFERROR(VLOOKUP(INDEX(checklistPesertaKemenkeu!$O$6:$O$1005,SMALL(IF(checklistPesertaKemenkeu!$AY$6:$AY$1005="Direkomendasikan",ROW($6:$1005)-5),3)),KotaKode,2,0),"-"),"")),"")} | L4: {=IFERROR(IF(OR(INDEX(checklistPesertaKemenkeu!$P$6:$P$1005,SMALL(IF(checklistPesertaKemenkeu!$AY$6:$AY$1005="Direkomendasikan",ROW($6:$1005)-5),3))="",INDEX(checklistPesertaKemenkeu!$J$6:$J$1005,SMALL(IF(checklistPesertaKemenkeu!$AY$6:$AY$1005="Direkomendasikan",ROW($6:$1005)-5),3))=""),"",IF(AND(COUNTIF(INDIRECT("K_"&MATCH(INDEX(checklistPesertaKemenkeu!$J$6:$J$1005,SMALL(IF(checklistPesertaKemenkeu!$AY$6:$AY$1005="Direkomendasikan",ROW($6:$1005)-5),3)),BidangList,0)),INDEX(checklistPesertaKemenkeu!$P$6:$P$1005,SMALL(IF(checklistPesertaKemenkeu!$AY$6:$AY$1005="Direkomendasikan",ROW($6:$1005)-5),3)))>0,COUNTIF(INDIRECT("'KERTAS KERJA'!K"&(SMALL(IF(checklistPesertaKemenkeu!$AY$6:$AY$1005="Direkomendasikan",ROW($6:$1005)-5),3)+5)&":O"&(SMALL(IF(checklistPesertaKemenkeu!$AY$6:$AY$1005="Direkomendasikan",ROW($6:$1005)-5),3)+5)),INDEX(checklistPesertaKemenkeu!$P$6:$P$1005,SMALL(IF(checklistPesertaKemenkeu!$AY$6:$AY$1005="Direkomendasikan",ROW($6:$1005)-5),3)))=1),IFERROR(VLOOKUP(INDEX(checklistPesertaKemenkeu!$P$6:$P$1005,SMALL(IF(checklistPesertaKemenkeu!$AY$6:$AY$1005="Direkomendasikan",ROW($6:$1005)-5),3)),KotaKode,2,0),"-"),"")),"")}
A5: =IF(C5="","",ROW()-1) | C5: {=IFERROR(INDEX(checklistPesertaKemenkeu!$F$6:$F$1005,SMALL(IF(checklistPesertaKemenkeu!$AY$6:$AY$1005="Direkomendasikan",ROW($6:$1005)-5),4)),"")} | D5: {=IFERROR(INDEX(checklistPesertaKemenkeu!$G$6:$G$1005,SMALL(IF(checklistPesertaKemenkeu!$AY$6:$AY$1005="Direkomendasikan",ROW($6:$1005)-5),4)),"")} | E5: {=IFERROR(INDEX(checklistPesertaKemenkeu!$H$6:$H$1005,SMALL(IF(checklistPesertaKemenkeu!$AY$6:$AY$1005="Direkomendasikan",ROW($6:$1005)-5),4)),"")} | F5: {=IFERROR(INDEX(checklistPesertaKemenkeu!$I$6:$I$1005,SMALL(IF(checklistPesertaKemenkeu!$AY$6:$AY$1005="Direkomendasikan",ROW($6:$1005)-5),4)),"")} | G5: {=IFERROR(INDEX(checklistPesertaKemenkeu!$J$6:$J$1005,SMALL(IF(checklistPesertaKemenkeu!$AY$6:$AY$1005="Direkomendasikan",ROW($6:$1005)-5),4)),"")} | H5: {=IFERROR(IF(OR(INDEX(checklistPesertaKemenkeu!$L$6:$L$1005,SMALL(IF(checklistPesertaKemenkeu!$AY$6:$AY$1005="Direkomendasikan",ROW($6:$1005)-5),4))="",INDEX(checklistPesertaKemenkeu!$J$6:$J$1005,SMALL(IF(checklistPesertaKemenkeu!$AY$6:$AY$1005="Direkomendasikan",ROW($6:$1005)-5),4))=""),"",IF(AND(COUNTIF(INDIRECT("K_"&MATCH(INDEX(checklistPesertaKemenkeu!$J$6:$J$1005,SMALL(IF(checklistPesertaKemenkeu!$AY$6:$AY$1005="Direkomendasikan",ROW($6:$1005)-5),4)),BidangList,0)),INDEX(checklistPesertaKemenkeu!$L$6:$L$1005,SMALL(IF(checklistPesertaKemenkeu!$AY$6:$AY$1005="Direkomendasikan",ROW($6:$1005)-5),4)))>0,COUNTIF(INDIRECT("'KERTAS KERJA'!K"&(SMALL(IF(checklistPesertaKemenkeu!$AY$6:$AY$1005="Direkomendasikan",ROW($6:$1005)-5),4)+5)&":O"&(SMALL(IF(checklistPesertaKemenkeu!$AY$6:$AY$1005="Direkomendasikan",ROW($6:$1005)-5),4)+5)),INDEX(checklistPesertaKemenkeu!$L$6:$L$1005,SMALL(IF(checklistPesertaKemenkeu!$AY$6:$AY$1005="Direkomendasikan",ROW($6:$1005)-5),4)))=1),IFERROR(VLOOKUP(INDEX(checklistPesertaKemenkeu!$L$6:$L$1005,SMALL(IF(checklistPesertaKemenkeu!$AY$6:$AY$1005="Direkomendasikan",ROW($6:$1005)-5),4)),KotaKode,2,0),"-"),"")),"")} | I5: {=IFERROR(IF(OR(INDEX(checklistPesertaKemenkeu!$M$6:$M$1005,SMALL(IF(checklistPesertaKemenkeu!$AY$6:$AY$1005="Direkomendasikan",ROW($6:$1005)-5),4))="",INDEX(checklistPesertaKemenkeu!$J$6:$J$1005,SMALL(IF(checklistPesertaKemenkeu!$AY$6:$AY$1005="Direkomendasikan",ROW($6:$1005)-5),4))=""),"",IF(AND(COUNTIF(INDIRECT("K_"&MATCH(INDEX(checklistPesertaKemenkeu!$J$6:$J$1005,SMALL(IF(checklistPesertaKemenkeu!$AY$6:$AY$1005="Direkomendasikan",ROW($6:$1005)-5),4)),BidangList,0)),INDEX(checklistPesertaKemenkeu!$M$6:$M$1005,SMALL(IF(checklistPesertaKemenkeu!$AY$6:$AY$1005="Direkomendasikan",ROW($6:$1005)-5),4)))>0,COUNTIF(INDIRECT("'KERTAS KERJA'!K"&(SMALL(IF(checklistPesertaKemenkeu!$AY$6:$AY$1005="Direkomendasikan",ROW($6:$1005)-5),4)+5)&":O"&(SMALL(IF(checklistPesertaKemenkeu!$AY$6:$AY$1005="Direkomendasikan",ROW($6:$1005)-5),4)+5)),INDEX(checklistPesertaKemenkeu!$M$6:$M$1005,SMALL(IF(checklistPesertaKemenkeu!$AY$6:$AY$1005="Direkomendasikan",ROW($6:$1005)-5),4)))=1),IFERROR(VLOOKUP(INDEX(checklistPesertaKemenkeu!$M$6:$M$1005,SMALL(IF(checklistPesertaKemenkeu!$AY$6:$AY$1005="Direkomendasikan",ROW($6:$1005)-5),4)),KotaKode,2,0),"-"),"")),"")} | J5: {=IFERROR(IF(OR(INDEX(checklistPesertaKemenkeu!$N$6:$N$1005,SMALL(IF(checklistPesertaKemenkeu!$AY$6:$AY$1005="Direkomendasikan",ROW($6:$1005)-5),4))="",INDEX(checklistPesertaKemenkeu!$J$6:$J$1005,SMALL(IF(checklistPesertaKemenkeu!$AY$6:$AY$1005="Direkomendasikan",ROW($6:$1005)-5),4))=""),"",IF(AND(COUNTIF(INDIRECT("K_"&MATCH(INDEX(checklistPesertaKemenkeu!$J$6:$J$1005,SMALL(IF(checklistPesertaKemenkeu!$AY$6:$AY$1005="Direkomendasikan",ROW($6:$1005)-5),4)),BidangList,0)),INDEX(checklistPesertaKemenkeu!$N$6:$N$1005,SMALL(IF(checklistPesertaKemenkeu!$AY$6:$AY$1005="Direkomendasikan",ROW($6:$1005)-5),4)))>0,COUNTIF(INDIRECT("'KERTAS KERJA'!K"&(SMALL(IF(checklistPesertaKemenkeu!$AY$6:$AY$1005="Direkomendasikan",ROW($6:$1005)-5),4)+5)&":O"&(SMALL(IF(checklistPesertaKemenkeu!$AY$6:$AY$1005="Direkomendasikan",ROW($6:$1005)-5),4)+5)),INDEX(checklistPesertaKemenkeu!$N$6:$N$1005,SMALL(IF(checklistPesertaKemenkeu!$AY$6:$AY$1005="Direkomendasikan",ROW($6:$1005)-5),4)))=1),IFERROR(VLOOKUP(INDEX(checklistPesertaKemenkeu!$N$6:$N$1005,SMALL(IF(checklistPesertaKemenkeu!$AY$6:$AY$1005="Direkomendasikan",ROW($6:$1005)-5),4)),KotaKode,2,0),"-"),"")),"")} | K5: {=IFERROR(IF(OR(INDEX(checklistPesertaKemenkeu!$O$6:$O$1005,SMALL(IF(checklistPesertaKemenkeu!$AY$6:$AY$1005="Direkomendasikan",ROW($6:$1005)-5),4))="",INDEX(checklistPesertaKemenkeu!$J$6:$J$1005,SMALL(IF(checklistPesertaKemenkeu!$AY$6:$AY$1005="Direkomendasikan",ROW($6:$1005)-5),4))=""),"",IF(AND(COUNTIF(INDIRECT("K_"&MATCH(INDEX(checklistPesertaKemenkeu!$J$6:$J$1005,SMALL(IF(checklistPesertaKemenkeu!$AY$6:$AY$1005="Direkomendasikan",ROW($6:$1005)-5),4)),BidangList,0)),INDEX(checklistPesertaKemenkeu!$O$6:$O$1005,SMALL(IF(checklistPesertaKemenkeu!$AY$6:$AY$1005="Direkomendasikan",ROW($6:$1005)-5),4)))>0,COUNTIF(INDIRECT("'KERTAS KERJA'!K"&(SMALL(IF(checklistPesertaKemenkeu!$AY$6:$AY$1005="Direkomendasikan",ROW($6:$1005)-5),4)+5)&":O"&(SMALL(IF(checklistPesertaKemenkeu!$AY$6:$AY$1005="Direkomendasikan",ROW($6:$1005)-5),4)+5)),INDEX(checklistPesertaKemenkeu!$O$6:$O$1005,SMALL(IF(checklistPesertaKemenkeu!$AY$6:$AY$1005="Direkomendasikan",ROW($6:$1005)-5),4)))=1),IFERROR(VLOOKUP(INDEX(checklistPesertaKemenkeu!$O$6:$O$1005,SMALL(IF(checklistPesertaKemenkeu!$AY$6:$AY$1005="Direkomendasikan",ROW($6:$1005)-5),4)),KotaKode,2,0),"-"),"")),"")} | L5: {=IFERROR(IF(OR(INDEX(checklistPesertaKemenkeu!$P$6:$P$1005,SMALL(IF(checklistPesertaKemenkeu!$AY$6:$AY$1005="Direkomendasikan",ROW($6:$1005)-5),4))="",INDEX(checklistPesertaKemenkeu!$J$6:$J$1005,SMALL(IF(checklistPesertaKemenkeu!$AY$6:$AY$1005="Direkomendasikan",ROW($6:$1005)-5),4))=""),"",IF(AND(COUNTIF(INDIRECT("K_"&MATCH(INDEX(checklistPesertaKemenkeu!$J$6:$J$1005,SMALL(IF(checklistPesertaKemenkeu!$AY$6:$AY$1005="Direkomendasikan",ROW($6:$1005)-5),4)),BidangList,0)),INDEX(checklistPesertaKemenkeu!$P$6:$P$1005,SMALL(IF(checklistPesertaKemenkeu!$AY$6:$AY$1005="Direkomendasikan",ROW($6:$1005)-5),4)))>0,COUNTIF(INDIRECT("'KERTAS KERJA'!K"&(SMALL(IF(checklistPesertaKemenkeu!$AY$6:$AY$1005="Direkomendasikan",ROW($6:$1005)-5),4)+5)&":O"&(SMALL(IF(checklistPesertaKemenkeu!$AY$6:$AY$1005="Direkomendasikan",ROW($6:$1005)-5),4)+5)),INDEX(checklistPesertaKemenkeu!$P$6:$P$1005,SMALL(IF(checklistPesertaKemenkeu!$AY$6:$AY$1005="Direkomendasikan",ROW($6:$1005)-5),4)))=1),IFERROR(VLOOKUP(INDEX(checklistPesertaKemenkeu!$P$6:$P$1005,SMALL(IF(checklistPesertaKemenkeu!$AY$6:$AY$1005="Direkomendasikan",ROW($6:$1005)-5),4)),KotaKode,2,0),"-"),"")),"")}
